Failure # 1 (occurred at 2024-03-07_11-09-06)
[36mray::PPO.restore()[39m (pid=40219, ip=192.168.1.195, actor_id=55856785c58e29048c2632ce01000000, repr=PPO)
  File "/home/ia/.local/lib/python3.8/site-packages/ray/tune/trainable/trainable.py", line 556, in restore
    raise ValueError(
ValueError: Could not recover from checkpoint as it does not exist on storage anymore. Got storage fs type `local` and path: /home/ia/Desktop/generic_platform/environments/UUV_Mono_Agent/Ia_models/3x3_3_100/PPO_UUVMonoAgentEnv_49608_00000_0_2024-03-05_15-11-40/checkpoint_000009
